<?xml version="1.0" ?>
<!-- =================================================================================== -->
<!-- |    This document was autogenerated by xacro from urdf_final.urdf                | -->
<!-- |    EDITING THIS FILE BY HAND IS NOT RECOMMENDED                                 | -->
<!-- =================================================================================== -->
<robot name="Mecanum_robot">
  <!-- <xacro:include filename="gazebo_control.xacro" /> -->
  <gazebo>
    <plugin filename="gz-sim-joint-state-publisher-system" name="gz::sim::systems::JointStatePublisher">
      <joint_name>chasis_joint</joint_name>
      <joint_name>back_right_wheel_joint</joint_name>
      <joint_name>back_left_wheel_joint</joint_name>
      <joint_name>front_right_wheel_joint</joint_name>
      <joint_name>front_left_wheel_joint</joint_name>
    </plugin>
  </gazebo>
  <!-- <gazebo>
        <plugin name="gazebo_ros_joint_pose_trajectory"
            filename="libgazebo_ros_joint_pose_trajectory.so">
            <update_rate>20</update_rate>
        </plugin>
    </gazebo> -->
  <joint name="camera_joint" type="fixed">
    <origin rpy="0 0 3.141592653589793" xyz="-0.255 0 -0.015"/>
    <parent link="chasis"/>
    <child link="camera_link"/>
  </joint>
  <link name="camera_link">
    <visual>
      <geometry>
        <box size="0.010 0.03 0.03"/>
      </geometry>
    </visual>
  </link>
  <joint name="camera_optical_joint" type="fixed">
    <origin rpy="-1.5707963267948966 0 -0.14279966607226333" xyz="0 0 0"/>
    <parent link="camera_link"/>
    <child link="camera_link_optical"/>
  </joint>
  <link name="camera_link_optical">
    <gazebo reference="camera_link">
      <material>Gazebo/Red</material>
      <sensor name="camera" type="camera">
        <always_on>true</always_on>
        <visualize>true</visualize>
        <update_rate>30</update_rate>
        <topic>camera/image_raw</topic>
        <gz_frame_id>camera_rgb_frame</gz_frame_id>
        <camera name="intel_realsense_r200">
          <camera_info_topic>camera/camera_info</camera_info_topic>
          <horizontal_fov>1.089</horizontal_fov>
          <image>
            <format>R8G8B8</format>
            <width>640</width>
            <height>480</height>
          </image>
          <clip>
            <near>0.05</near>
            <far>8.0</far>
          </clip>
        </camera>
        <plugin filename="libgazebo_ros_camera.so" name="camera_driver">
          <frame_name>camera_link_optical</frame_name>
        </plugin>
      </sensor>
    </gazebo>
  </link>
  <joint name="lidar_joint" type="fixed">
    <origin rpy="0 0 0" xyz="0 0 0"/>
    <parent link="chasis"/>
    <child link="lidar_frame"/>
  </joint>
  <link name="lidar_frame">
    <visual>
      <geometry>
        <cylinder length="0.04" radius="0.05"/>
        <material name="red"/>
      </geometry>
    </visual>
    <collision>
      <geometry>
        <cylinder length="0.04" radius="0.05"/>
      </geometry>
    </collision>
    <inertial>
      <origin rpy="0 0 0" xyz="0 0 0"/>
      <mass value="0.1"/>
      <inertia ixx="7.583333333333335e-05" ixy="0.0" ixz="0.0" iyy="7.583333333333335e-05" iyz="0.0" izz="0.00012500000000000003"/>
    </inertial>
    <gazebo reference="lidar_head_link">
      <sensor name="lidar_head_link" type="gpu_lidar">
        <always_on>true</always_on>
        <visualize>true</visualize>
        <pose relative_to="lidar_frame">0 0 0 0 0 0</pose>
        <update_rate>30</update_rate>
        <gz_frame_id>lidar_head_link</gz_frame_id>
        <topic>scan</topic>
        <lidar>
          <scan>
            <horizontal>
              <samples>640</samples>
              <resolution>1</resolution>
              <min_angle>-1.396263</min_angle>
              <max_angle>1.396263</max_angle>
            </horizontal>
            <vertical>
              <samples>1</samples>
              <resolution>0.01</resolution>
              <min_angle>0</min_angle>
              <max_angle>0</max_angle>
            </vertical>
          </scan>
          <range>
            <min>0.08</min>
            <max>10.0</max>
            <resolution>0.01</resolution>
          </range>
          <frame_id>/lidar_head_link</frame_id>
        </lidar>
      </sensor>
    </gazebo>
    <gazebo>
      <plugin filename="gz-sim-sensors-system" name="gz::sim::systems::Sensors">
        <render_engine>ogre2</render_engine>
      </plugin>
    </gazebo>
  </link>
  <material name="red">
    <color rgba="1 0 0 1"/>
  </material>
  <material name="blue">
    <color rgba="0 0 1 1"/>
  </material>
  <material name="green">
    <color rgba="0 1 0 1"/>
  </material>
  <material name="brown">
    <color rgba="0.65 0.16 0.16 1"/>
  </material>
  <material name="violet">
    <color rgba="0.56 0 1 1"/>
  </material>
  <!-- <xacro:include filename="gazeboDepthCamera.xacro" /> -->
  <link name="base_link">
    <inertial>
      <origin xyz="0 0 0"/>
      <mass value="0.1"/>
      <inertia ixx="0.001" ixy="0.0" ixz="0.0" iyy="0.001" iyz="0.0" izz="0.001"/>
    </inertial>
    <collision>
      <origin xyz="0 0 0"/>
      <geometry>
        <box size="0.01 0.01 0.01"/>
      </geometry>
    </collision>
  </link>
  <link name="chasis">
    <inertial>
      <origin rpy="0 0 0" xyz="-8.294E-05 -7.7011E-11 -0.023972"/>
      <mass value="6.5996"/>
      <inertia ixx="0.043356" ixy="-1.6809E-08" ixz="-1.7057E-07" iyy="0.13461" iyz="3.8673E-11" izz="0.17533"/>
    </inertial>
    <visual>
      <origin rpy="0 0 0" xyz="0 0 0"/>
      <geometry>
        <mesh filename="package://mecanum_robot_simulation/description/meshes/chasis.STL"/>
      </geometry>
      <material name="blue"/>
    </visual>
    <collision>
      <origin rpy="0 0 0" xyz="0 0 -0.025"/>
      <geometry>
        <box size="0.50 0.40 0.05"/>
      </geometry>
    </collision>
  </link>
  <joint name="chasis_joint" type="fixed">
    <origin rpy="0 0 0" xyz="0 0 0"/>
    <parent link="base_link"/>
    <child link="chasis"/>
  </joint>
  <link name="back_right_wheel_link">
    <inertial>
      <origin rpy="0 0 0" xyz="1.624E-12 -3.4926E-12 0.021031"/>
      <mass value="0.049871"/>
      <inertia ixx="5.3189E-06" ixy="1.2084E-15" ixz="-9.388E-17" iyy="5.3189E-06" iyz="1.994E-16" izz="6.4396E-06"/>
    </inertial>
    <visual>
      <origin rpy="0 0 0" xyz="0 0 0"/>
      <geometry>
        <mesh filename="package://mecanum_robot_simulation/description/meshes/back_right_wheel.STL"/>
      </geometry>
      <material name="green"/>
    </visual>
    <collision>
      <origin rpy="0 0 0" xyz="0 0 0"/>
      <geometry>
        <cylinder length="0.039" radius="0.029"/>
      </geometry>
    </collision>
  </link>
  <joint name="back_right_wheel_joint" type="continuous">
    <origin rpy="1.5708 0 3.1416" xyz="0.1175 0.113 -0.03"/>
    <parent link="chasis"/>
    <child link="back_right_wheel_link"/>
    <axis xyz="0 0 1"/>
    <limit effort="200" lower="-3.14" upper="3.14" velocity="5"/>
  </joint>
  <link name="back_left_wheel_link">
    <inertial>
      <origin rpy="0 0 0" xyz="-6.2922E-13 3.7938E-12 0.021031"/>
      <mass value="0.049871"/>
      <inertia ixx="5.3189E-06" ixy="5.4099E-16" ixz="3.9906E-17" iyy="5.3189E-06" iyz="-2.1312E-16" izz="6.4396E-06"/>
    </inertial>
    <visual>
      <origin rpy="0 0 0" xyz="0 0 0"/>
      <geometry>
        <mesh filename="package://mecanum_robot_simulation/description/meshes/back_left_wheel.STL"/>
      </geometry>
      <material name="green"/>
    </visual>
    <collision>
      <origin rpy="0 0 0" xyz="0 0 0"/>
      <geometry>
        <cylinder length="0.039" radius="0.029"/>
      </geometry>
    </collision>
  </link>
  <joint name="back_left_wheel_joint" type="continuous">
    <origin rpy="-1.5708 0 3.1416" xyz="0.1175 -0.113 -0.03"/>
    <parent link="chasis"/>
    <child link="back_left_wheel_link"/>
    <axis xyz="0 0 1"/>
    <limit effort="200" lower="-3.14" upper="3.14" velocity="5"/>
  </joint>
  <link name="front_right_wheel_link">
    <inertial>
      <origin rpy="0 0 0" xyz="-6.2939E-13 3.7953E-12 0.021031"/>
      <mass value="0.049871"/>
      <inertia ixx="5.3189E-06" ixy="5.4109E-16" ixz="3.6773E-17" iyy="5.3189E-06" iyz="-2.1556E-16" izz="6.4396E-06"/>
    </inertial>
    <visual>
      <origin rpy="0 0 0" xyz="0 0 0"/>
      <geometry>
        <mesh filename="package://mecanum_robot_simulation/description/meshes/front_right_wheel.STL"/>
      </geometry>
      <material name="green"/>
    </visual>
    <collision>
      <origin rpy="0 0 0" xyz="0 0 0"/>
      <geometry>
        <cylinder length="0.039" radius="0.029"/>
      </geometry>
    </collision>
  </link>
  <joint name="front_right_wheel_joint" type="continuous">
    <origin rpy="1.5708 0 3.1416" xyz="-0.1175 0.113 -0.03"/>
    <parent link="chasis"/>
    <child link="front_right_wheel_link"/>
    <axis xyz="0 0 1"/>
    <limit effort="200" lower="-3.14" upper="3.14" velocity="5"/>
  </joint>
  <link name="front_left_wheel_link">
    <inertial>
      <origin rpy="0 0 0" xyz="1.451E-12 -3.5752E-12 0.021031"/>
      <mass value="0.049871"/>
      <inertia ixx="5.3189E-06" ixy="1.1259E-15" ixz="-8.0856E-17" iyy="5.3189E-06" iyz="2.0104E-16" izz="6.4396E-06"/>
    </inertial>
    <visual>
      <origin rpy="0 0 0" xyz="0 0 0"/>
      <geometry>
        <mesh filename="package://mecanum_robot_simulation/description/meshes/front_left_wheel.STL"/>
        <material name="green"/>
      </geometry>
    </visual>
    <collision>
      <origin rpy="0 0 0" xyz="0 0 0"/>
      <geometry>
        <cylinder length="0.039" radius="0.029"/>
      </geometry>
    </collision>
  </link>
  <joint name="front_left_wheel_joint" type="continuous">
    <origin rpy="-1.5708 0 3.1416" xyz="-0.1175 -0.113 -0.03"/>
    <parent link="chasis"/>
    <child link="front_left_wheel_link"/>
    <axis xyz="0 0 1"/>
    <limit effort="200" lower="-3.14" upper="3.14" velocity="5"/>
  </joint>
</robot>
