<?xml version="1.0"?>

<robot name="Mecanum_robot" xmlns:xacro="http://www.ros.org/wiki/xacro">

  <xacro:include filename="gazebo_control.xacro" />

  <xacro:include filename="gazeboCamera.xacro" />

  <xacro:include filename="gazeboLidar.xacro" />

  <xacro:include filename="gazeboIMU.xacro" />

  <!-- <xacro:include filename="gazeboDepthCamera.xacro" /> -->

  <link name="base_link">
    <inertial>
      <origin xyz="0 0 0" />
      <mass value="0.1" />
      <inertia ixx="0.001" ixy="0.0" ixz="0.0" iyy="0.001" iyz="0.0" izz="0.001" />
    </inertial>
    <collision>
      <origin xyz="0 0 0" />
      <geometry>
        <box size="0.01 0.01 0.01" />
      </geometry>
    </collision>
  </link>

  <link name="base_footprint_link">
    <visual>
        <origin xyz="0 0 0" rpy="0 0 0" />
        <geometry>
            <box size="0.235 0.226 0.001"/>  <!-- Adjust height if needed -->
        </geometry>
        <material name="yellow">
            <color rgba="1 1 0 0.5"/> <!-- Semi-transparent yellow for visibility -->
        </material>
    </visual>
</link>

<!-- Joint to connect the footprint to the base link -->
<joint name="base_footprint_joint" type="fixed">
    <parent link="chasis"/>
    <child link="base_footprint_link"/>
    <origin xyz="0 0 0" rpy="0 0 0"/>
</joint>

  <link name="chasis">
    <inertial>
      <origin xyz="-8.294E-05 -7.7011E-11 -0.023972" rpy="0 0 0" />
      <mass value="6.5996" />
      <inertia ixx="0.043356" ixy="-1.6809E-08" ixz="-1.7057E-07" iyy="0.13461" iyz="3.8673E-11" izz="0.17533" />
    </inertial>
    <visual>
      <origin xyz="0 0 0" rpy="0 0 0" />
      <geometry>
        <mesh filename="file:///home/gunner/mecanum_robot/src/mecanum_robot_simulation/description/meshes/chasis.STL"/>
      </geometry>
      <material name="blue">
        <color rgba="0 0 1 1"/>
      </material>
    </visual>  
    <collision>
      <origin xyz="0 0 -0.025" rpy="0 0 0" />
      <geometry>
        <box size="0.50 0.40 0.05" />
      </geometry>
    </collision>
  </link>
  <joint name="chasis_joint" type="fixed">
    <origin xyz="0 0 0" rpy="0 0 0" />
    <parent link="base_link" />
    <child link="chasis" />
  </joint>

  <gazebo reference='chasis_joint'>
    <preserveFixedJoint>true</preserveFixedJoint>
  </gazebo>

  <link name="back_left_wheel_link">
    <inertial>
      <origin xyz="1.624E-12 -3.4926E-12 0.021031" rpy="0 0 0" />
      <mass value="0.049871" />
      <inertia ixx="5.3189E-06" ixy="1.2084E-15" ixz="-9.388E-17" iyy="5.3189E-06" iyz="1.994E-16" izz="6.4396E-06" />
    </inertial>
    <visual>
      <origin xyz="0 0 0" rpy="0 0 0" />
      <geometry>
        <mesh filename="file:///home/gunner/mecanum_robot/src/mecanum_robot_simulation/description/meshes/back_right_wheel.STL"/>
      </geometry>
      <material name="green">
        <color rgba="0 1 0 1"/>
      </material>
    </visual>
    <collision>
      <origin xyz="0 0 0" rpy="0 0 0" />
      <geometry>
        <cylinder radius="0.029" length="0.039"/>
      </geometry>
    </collision>
  </link>
  <joint name="back_left_wheel_joint" type="continuous">
    <origin xyz="-0.1175 0.113 -0.03" rpy="1.5708 0 3.1416" />
    <parent link="chasis" />
    <child link="back_left_wheel_link" />
    <axis xyz="0 0 1" />
    <limit lower="-3.14" upper="3.14" effort="200" velocity="15" />
  </joint>

  <link name="back_right_wheel_link">
    <inertial>
      <origin xyz="-6.2922E-13 3.7938E-12 0.021031" rpy="0 0 0" />
      <mass value="0.049871" />
      <inertia ixx="5.3189E-06" ixy="5.4099E-16" ixz="3.9906E-17" iyy="5.3189E-06" iyz="-2.1312E-16" izz="6.4396E-06" />
    </inertial>
    <visual>
      <origin xyz="0 0 0" rpy="0 0 0" />
      <geometry>
        <mesh filename="file:///home/gunner/mecanum_robot/src/mecanum_robot_simulation/description/meshes/back_left_wheel.STL"/>
      </geometry>
      <material name="green">
        <color rgba="0 1 0 1"/>
      </material>
    </visual>
    <collision>
      <origin xyz="0 0 0" rpy="0 0 0" />
      <geometry>
        <cylinder radius="0.029" length="0.039"/>
      </geometry>
    </collision>
  </link>
  <joint name="back_right_wheel_joint" type="continuous">
    <origin xyz="-0.1175 -0.113 -0.03" rpy="-1.5708 0 -3.1416" />
    <parent link="chasis" />
    <child link="back_right_wheel_link" />
    <axis xyz="0 0 1" />
    <limit lower="-3.14" upper="3.14" effort="200" velocity="15" />
  </joint>

  <link name="front_left_wheel_link">
    <inertial>
      <origin xyz="-6.2939E-13 3.7953E-12 0.021031" rpy="0 0 0" />
      <mass value="0.049871" />
      <inertia ixx="5.3189E-06" ixy="5.4109E-16" ixz="3.6773E-17" iyy="5.3189E-06" iyz="-2.1556E-16" izz="6.4396E-06" />
    </inertial>
    <visual>
      <origin xyz="0 0 0" rpy="0 0 0" />
      <geometry>
        <mesh filename="file:///home/gunner/mecanum_robot/src/mecanum_robot_simulation/description/meshes/front_right_wheel.STL"/>
      </geometry>
      <material name="green">
        <color rgba="0 1 0 1"/>
      </material>
    </visual>
    <collision>
      <origin xyz="0 0 0" rpy="0 0 0" />
      <geometry>
        <cylinder radius="0.029" length="0.039"/>
      </geometry>
    </collision>
  </link>
  <joint name="front_left_wheel_joint" type="continuous">
    <origin xyz="0.1175 0.113 -0.03" rpy="1.5708 0 3.1416" />
    <parent link="chasis" />
    <child link="front_left_wheel_link" />
    <axis xyz="0 0 1" />
    <limit lower="-3.14" upper="3.14" effort="200" velocity="15" />
  </joint>

  <link name="front_right_wheel_link">
    <inertial>
      <origin xyz="1.451E-12 -3.5752E-12 0.021031" rpy="0 0 0" />
      <mass value="0.049871" />
      <inertia ixx="5.3189E-06" ixy="1.1259E-15" ixz="-8.0856E-17" iyy="5.3189E-06" iyz="2.0104E-16" izz="6.4396E-06" />
    </inertial>
    <visual>
      <origin xyz="0 0 0" rpy="0 0 0" />
      <geometry>
        <mesh filename="file:///home/gunner/mecanum_robot/src/mecanum_robot_simulation/description/meshes/front_left_wheel.STL"/>
      </geometry>
      <material name="green">
        <color rgba="0 1 0 1"/>
      </material>
    </visual>
    <collision>
      <origin xyz="0 0 0" rpy="0 0 0" />
      <geometry>
        <cylinder radius="0.029" length="0.039"/>
      </geometry>
    </collision>
  </link>
  <joint name="front_right_wheel_joint" type="continuous">
    <origin xyz="0.1175 -0.113 -0.03" rpy="-1.5708 0 3.1416" />
    <parent link="chasis" />
    <child link="front_right_wheel_link" />
    <axis xyz="0 0 1" />
    <limit lower="-3.14" upper="3.14" effort="200" velocity="15" />
  </joint>

  <gazebo reference="chasis">
    <mu1>1.0</mu1>
    <mu2>1.0</mu2>
  </gazebo>

  <gazebo reference="back_right_wheel_link">
      <mu1>1.0</mu1>
      <mu2>1.0</mu2>
  </gazebo>

  <gazebo reference="front_left_wheel_link">
      <mu1>1.0</mu1>
      <mu2>1.0</mu2>
  </gazebo>

  <gazebo reference="back_left_wheel_link">
    <mu1>1.0</mu1>
    <mu2>1.0</mu2>
  </gazebo>

  <gazebo reference="front_right_wheel_link">
    <mu1>1.0</mu1>
    <mu2>1.0</mu2>
  </gazebo>

</robot>