<?xml version="1.0"?>

<robot name="Mecanum_robot" xmlns:xacro="http://www.ros.org/wiki/xacro">

  <!-- <xacro:include filename="gazebo_control.xacro" /> -->

  <!-- <xacro:include filename="gazeboTransforms_update.xacro" />

  <xacro:include filename="gazeboCamera.xacro" /> -->

  <!-- <xacro:include filename="/home/gunner/mecanum_robot/src/Mecanum_Robot_Simulation/description/urdf/gazeboLidar.xacro" /> -->

  <!-- <xacro:include filename="gazeboDepthCamera.xacro" /> -->

  <material name="red">
    <color rgba="1 0 0 1"/>
  </material>

  <material name="blue">
    <color rgba="0 0 1 1"/>
  </material>

  <material name="green">
    <color rgba="0 1 0 1"/>
  </material>

  <material name="brown">
    <color rgba="0.65 0.16 0.16 1"/>
  </material>

  <material name="violet">
    <color rgba="0.56 0 1 1"/>
  </material>

  <link name="base_link"></link>

  <link name="chasis">
    <inertial>
      <origin xyz="-8.294E-05 -7.7011E-11 -0.023972" rpy="0 0 0" />
      <mass value="6.5996" />
      <inertia ixx="0.043356" ixy="-1.6809E-08" ixz="-1.7057E-07" iyy="0.13461" iyz="3.8673E-11" izz="0.17533" />
    </inertial>
    <visual>
      <origin xyz="0 0 0" rpy="0 0 0" />
      <geometry>
        <mesh filename="/home/gunner/mecanum_robot/src/Mecanum_Robot_Simulation/description/meshes/chasis.STL"/>
      </geometry>
      <material name="blue" />
    </visual>  
    <collision>
      <origin xyz="0 0 0" rpy="0 0 0" />
      <geometry>
        <mesh filename="/home/gunner/mecanum_robot/src/Mecanum_Robot_Simulation/description/meshes/chasis.STL"/>
      </geometry>
    </collision>
  </link>
  <joint name="chasis_joint" type="fixed">
    <origin xyz="0 0 0" rpy="0 0 0" />
    <parent link="base_link" />
    <child link="chasis" />
  </joint>

  <link name="back_right_wheel_link">
    <inertial>
      <origin xyz="1.624E-12 -3.4926E-12 0.021031" rpy="0 0 0" />
      <mass value="0.049871" />
      <inertia ixx="5.3189E-06" ixy="1.2084E-15" ixz="-9.388E-17" iyy="5.3189E-06" iyz="1.994E-16" izz="6.4396E-06" />
    </inertial>
    <visual>
      <origin xyz="0 0 0" rpy="0 0 0" />
      <geometry>
        <mesh filename="/home/gunner/mecanum_robot/src/Mecanum_Robot_Simulation/description/meshes/back_right_wheel.STL"/>
      </geometry>
      <material name="green" />
    </visual>
    <collision>
      <origin xyz="0 0 0" rpy="0 0 0" />
      <geometry>
        <mesh filename="/home/gunner/mecanum_robot/src/Mecanum_Robot_Simulation/description/meshes/back_right_wheel.STL"/>
      </geometry>
    </collision>
  </link>
  <joint name="back_right_wheel_joint" type="continuous">
    <origin xyz="0.1175 0.113 -0.03" rpy="1.5708 0 3.1416" />
    <parent link="chasis" />
    <child link="back_right_wheel_link" />
    <axis xyz="0 0 1" />
    <limit lower="-3.14" upper="3.14" effort="200" velocity="5" />
  </joint>

  <link name="back_left_wheel_link">
    <inertial>
      <origin xyz="-6.2922E-13 3.7938E-12 0.021031" rpy="0 0 0" />
      <mass value="0.049871" />
      <inertia ixx="5.3189E-06" ixy="5.4099E-16" ixz="3.9906E-17" iyy="5.3189E-06" iyz="-2.1312E-16" izz="6.4396E-06" />
    </inertial>
    <visual>
      <origin xyz="0 0 0" rpy="0 0 0" />
      <geometry>
        <mesh filename="/home/gunner/mecanum_robot/src/Mecanum_Robot_Simulation/description/meshes/back_left_wheel.STL"/>
      </geometry>
      <material name="green" />
    </visual>
    <collision>
      <origin xyz="0 0 0" rpy="0 0 0" />
      <geometry>
        <mesh filename="/home/gunner/mecanum_robot/src/Mecanum_Robot_Simulation/description/meshes/back_left_wheel.STL"/>
      </geometry>
    </collision>
  </link>
  <joint name="back_left_wheel_joint" type="continuous">
    <origin xyz="0.1175 -0.113 -0.03" rpy="-1.5708 0 3.1416" />
    <parent link="chasis" />
    <child link="back_left_wheel_link" />
    <axis xyz="0 0 1" />
    <limit lower="-3.14" upper="3.14" effort="200" velocity="5" />
  </joint>

  <link name="front_right_wheel_link">
    <inertial>
      <origin xyz="-6.2939E-13 3.7953E-12 0.021031" rpy="0 0 0" />
      <mass value="0.049871" />
      <inertia ixx="5.3189E-06" ixy="5.4109E-16" ixz="3.6773E-17" iyy="5.3189E-06" iyz="-2.1556E-16" izz="6.4396E-06" />
    </inertial>
    <visual>
      <origin xyz="0 0 0" rpy="0 0 0" />
      <geometry>
        <mesh filename="/home/gunner/mecanum_robot/src/Mecanum_Robot_Simulation/description/meshes/front_right_wheel.STL"/>
      </geometry>
      <material name="green" />
    </visual>
    <collision>
      <origin xyz="0 0 0" rpy="0 0 0" />
      <geometry>
        <mesh filename="/home/gunner/mecanum_robot/src/Mecanum_Robot_Simulation/description/meshes/front_right_wheel.STL"/>
      </geometry>
    </collision>
  </link>
  <joint name="front_right_wheel_joint" type="continuous">
    <origin xyz="-0.1175 0.113 -0.03" rpy="1.5708 0 3.1416" />
    <parent link="chasis" />
    <child link="front_right_wheel_link" />
    <axis xyz="0 0 1" />
    <limit lower="-3.14" upper="3.14" effort="200" velocity="5" />
  </joint>

  <link name="front_left_wheel_link">
    <inertial>
      <origin xyz="1.451E-12 -3.5752E-12 0.021031" rpy="0 0 0" />
      <mass value="0.049871" />
      <inertia ixx="5.3189E-06" ixy="1.1259E-15" ixz="-8.0856E-17" iyy="5.3189E-06" iyz="2.0104E-16" izz="6.4396E-06" />
    </inertial>
    <visual>
      <origin xyz="0 0 0" rpy="0 0 0" />
      <geometry>
        <mesh filename="/home/gunner/mecanum_robot/src/Mecanum_Robot_Simulation/description/meshes/front_left_wheel.STL"/>
        <material name="green" />
      </geometry>
    </visual>
    <collision>
      <origin xyz="0 0 0" rpy="0 0 0" />
      <geometry>
        <mesh filename="/home/gunner/mecanum_robot/src/Mecanum_Robot_Simulation/description/meshes/front_left_wheel.STL"/>
      </geometry>
    </collision>
  </link>
  <joint name="front_left_wheel_joint" type="continuous">
    <origin xyz="-0.1175 -0.113 -0.03" rpy="-1.5708 0 3.1416" />
    <parent link="chasis" />
    <child link="front_left_wheel_link" />
    <axis xyz="0 0 1" />
    <limit lower="-3.14" upper="3.14" effort="200" velocity="5" />
  </joint>

  <xacro:macro name="inertial_cylinder" params="mass length radius *origin">
      <inertial>
          <xacro:insert_block name="origin"/>
          <mass value="${mass}" />
          <inertia ixx="${(1/12) * mass * (3*radius*radius + length*length)}" ixy="0.0" ixz="0.0"
                  iyy="${(1/12) * mass * (3*radius*radius + length*length)}" iyz="0.0"
                  izz="${(1/2) * mass * (radius*radius)}" />
      </inertial>
  </xacro:macro>

  <joint name="lidar_joint" type="fixed">
      <origin xyz="0 0 0" rpy="0 0 0" />
      <parent link="chasis" />
      <child link="lidar_frame" />
  </joint>

  <link name="lidar_frame">
      <visual>
          <geometry>
              <cylinder radius="0.05" length="0.04"/>
              <material name="red" />
          </geometry>    
      </visual>
      <collision>
          <geometry>
              <cylinder radius="0.05" length="0.04"/>
          </geometry>
      </collision>
      <xacro:inertial_cylinder mass="0.1" length="0.04" radius="0.05">
          <origin xyz="0 0 0" rpy="0 0 0"/>
      </xacro:inertial_cylinder>
  </link>    

  <gazebo>
    <sensor name="lidar_head_link" type="gpu_lidar">
      <gz_frame_id>lidar_head_link</gz_frame_id>
      <topic>scan</topic>
      <update_rate>30</update_rate>
      <lidar>
        <scan>
          <horizontal>
            <samples>2800</samples>
            <resolution>1</resolution>
            <min_angle>-3.14</min_angle>
            <max_angle>3.14</max_angle>
          </horizontal>
          <vertical>
            <samples>1</samples>
            <resolution>0.1</resolution>
            <min_angle>0.0</min_angle>
            <max_angle>0.0</max_angle>
          </vertical>
        </scan>
        <range>
          <min>0.2</min>
          <max>30.0</max>
          <resolution>0.01</resolution>
        </range>
        <frame_id>/lidar_head_link</frame_id>
      </lidar>
      <alwaysOn>true</alwaysOn>
      <visualize>true</visualize>
    </sensor>
    <plugin filename="gz-sim-sensors-system" name="gz::sim::systems::Sensors">
      <render_engine>ogre2</render_engine>
    </plugin>
  </gazebo>

</robot>